Ah, a "list index out of range" error! This is very specific and helpful. In Python, this typically occurs when you try to access an array index that doesn't exist. Given your code and this error, there are a few likely culprits:

1. In `process_observations()`, you're accessing ancestor_ids with fixed indices:
```python
"kingdom": ancestor_ids[0] if len(ancestor_ids) > 0 else None,
"phylum": ancestor_ids[1] if len(ancestor_ids) > 1 else None,
"class": ancestor_ids[2] if len(ancestor_ids) > 2 else None,
...
```

2. Some observation might have an `ancestor_ids` array that's empty or shorter than expected, and despite your checks:
```python
if not ancestor_ids or len(ancestor_ids) < 2:  # Need at least kingdom level
    continue
```
...something is still getting through.

Here's what I suggest:

```python
def process_observations(observations: List[Dict]) -> pd.DataFrame:
    processed_data = []
    
    for obs in observations:
        try:  # Add try/except around the whole processing
            if not obs.get("taxon") or not obs.get("id"):
                continue
                
            taxon = obs["taxon"]
            ancestor_ids = taxon.get("ancestor_ids", [])
            
            # More defensive check of ancestor_ids
            if not isinstance(ancestor_ids, list):
                continue
                
            # Create a padded version of ancestor_ids
            padded_ancestors = ancestor_ids + [None] * 7  # Ensure we have enough elements
            
            processed_data.append({
                "observation_id": obs["id"],
                "taxon_id": taxon["id"],
                "name": taxon["name"],
                "rank": taxon["rank"],
                "kingdom": padded_ancestors[0],
                "phylum": padded_ancestors[1],
                "class": padded_ancestors[2],
                "order": padded_ancestors[3],
                "family": padded_ancestors[4],
                "genus": padded_ancestors[5],
                "species": taxon["id"],
                "common_name": taxon.get("preferred_common_name", ""),
                "observed_on": obs.get("observed_on"),
                "photo_url": obs.get("photos", [{}])[0].get("url", "")
            })
            
        except Exception as e:
            print(f"Error processing observation {obs.get('id')}: {str(e)}")
            print(f"ancestor_ids: {taxon.get('ancestor_ids')}")
            continue
            
    return pd.DataFrame(processed_data)
```

The key changes:
1. Added a try/except block around the whole processing
2. Added type checking for ancestor_ids
3. Created a padded version of ancestor_ids array to prevent index errors
4. Added more detailed error logging

This should prevent the index out of range error while also helping identify which observations are causing problems. You might find that some taxa have unexpected ancestry structures or that the API is returning data in an unexpected format for certain observations.

Would you like me to add more detailed debugging output to help track down exactly which observation is causing the problem?